[2023-11-09T15:23:53.211+0000] {taskinstance.py:1159} INFO - Dependencies all met for dep_context=non-requeueable deps ti=<TaskInstance: essai.t2 scheduled__2023-11-08T15:18:44.692033+00:00 [queued]>
[2023-11-09T15:23:53.221+0000] {taskinstance.py:1159} INFO - Dependencies all met for dep_context=requeueable deps ti=<TaskInstance: essai.t2 scheduled__2023-11-08T15:18:44.692033+00:00 [queued]>
[2023-11-09T15:23:53.222+0000] {taskinstance.py:1361} INFO - Starting attempt 2 of 2
[2023-11-09T15:23:53.235+0000] {taskinstance.py:1382} INFO - Executing <Task(_PythonDecoratedOperator): t2> on 2023-11-08 15:18:44.692033+00:00
[2023-11-09T15:23:53.242+0000] {standard_task_runner.py:57} INFO - Started process 10710 to run task
[2023-11-09T15:23:53.245+0000] {standard_task_runner.py:84} INFO - Running: ['***', 'tasks', 'run', 'essai', 't2', 'scheduled__2023-11-08T15:18:44.692033+00:00', '--job-id', '39', '--raw', '--subdir', 'DAGS_FOLDER/Part1.py', '--cfg-path', '/tmp/tmprci3n7m8']
[2023-11-09T15:23:53.247+0000] {standard_task_runner.py:85} INFO - Job 39: Subtask t2
[2023-11-09T15:23:53.295+0000] {task_command.py:416} INFO - Running <TaskInstance: essai.t2 scheduled__2023-11-08T15:18:44.692033+00:00 [running]> on host fb26c01043df
[2023-11-09T15:23:53.378+0000] {taskinstance.py:1662} INFO - Exporting env vars: AIRFLOW_CTX_DAG_EMAIL='***@example.com' AIRFLOW_CTX_DAG_OWNER='***' AIRFLOW_CTX_DAG_ID='essai' AIRFLOW_CTX_TASK_ID='t2' AIRFLOW_CTX_EXECUTION_DATE='2023-11-08T15:18:44.692033+00:00' AIRFLOW_CTX_TRY_NUMBER='2' AIRFLOW_CTX_DAG_RUN_ID='scheduled__2023-11-08T15:18:44.692033+00:00'
[2023-11-09T15:23:53.381+0000] {logging_mixin.py:151} INFO - jaweek hlow
[2023-11-09T15:23:53.382+0000] {taskinstance.py:1937} ERROR - Task failed with exception
Traceback (most recent call last):
  File "/home/airflow/.local/lib/python3.8/site-packages/airflow/decorators/base.py", line 221, in execute
    return_value = super().execute(context)
  File "/home/airflow/.local/lib/python3.8/site-packages/airflow/operators/python.py", line 192, in execute
    return_value = self.execute_callable()
  File "/home/airflow/.local/lib/python3.8/site-packages/airflow/operators/python.py", line 209, in execute_callable
    return self.python_callable(*self.op_args, **self.op_kwargs)
  File "/opt/airflow/dags/Part1.py", line 24, in data_transform
    data = data[data['Type local'] == 'appartement']
UnboundLocalError: local variable 'data' referenced before assignment
[2023-11-09T15:23:53.391+0000] {taskinstance.py:1400} INFO - Marking task as FAILED. dag_id=essai, task_id=t2, execution_date=20231108T151844, start_date=20231109T152353, end_date=20231109T152353
[2023-11-09T15:23:53.403+0000] {standard_task_runner.py:104} ERROR - Failed to execute job 39 for task t2 (local variable 'data' referenced before assignment; 10710)
[2023-11-09T15:23:53.418+0000] {local_task_job_runner.py:228} INFO - Task exited with return code 1
[2023-11-09T15:23:53.435+0000] {taskinstance.py:2778} INFO - 0 downstream tasks scheduled from follow-on schedule check
