[2023-11-12T16:37:34.300+0000] {taskinstance.py:1159} INFO - Dependencies all met for dep_context=non-requeueable deps ti=<TaskInstance: Projet1.create_table manual__2023-11-12T16:37:27.510829+00:00 [queued]>
[2023-11-12T16:37:34.310+0000] {taskinstance.py:1159} INFO - Dependencies all met for dep_context=requeueable deps ti=<TaskInstance: Projet1.create_table manual__2023-11-12T16:37:27.510829+00:00 [queued]>
[2023-11-12T16:37:34.311+0000] {taskinstance.py:1361} INFO - Starting attempt 1 of 1
[2023-11-12T16:37:34.326+0000] {taskinstance.py:1382} INFO - Executing <Task(PostgresOperator): create_table> on 2023-11-12 16:37:27.510829+00:00
[2023-11-12T16:37:34.332+0000] {standard_task_runner.py:57} INFO - Started process 29694 to run task
[2023-11-12T16:37:34.335+0000] {standard_task_runner.py:84} INFO - Running: ['***', 'tasks', 'run', 'Projet1', 'create_table', 'manual__2023-11-12T16:37:27.510829+00:00', '--job-id', '114', '--raw', '--subdir', 'DAGS_FOLDER/Projet.py', '--cfg-path', '/tmp/tmpsjzwk4sr']
[2023-11-12T16:37:34.337+0000] {standard_task_runner.py:85} INFO - Job 114: Subtask create_table
[2023-11-12T16:37:34.391+0000] {task_command.py:416} INFO - Running <TaskInstance: Projet1.create_table manual__2023-11-12T16:37:27.510829+00:00 [running]> on host fb26c01043df
[2023-11-12T16:37:34.480+0000] {taskinstance.py:1662} INFO - Exporting env vars: AIRFLOW_CTX_DAG_OWNER='***' AIRFLOW_CTX_DAG_ID='Projet1' AIRFLOW_CTX_TASK_ID='create_table' AIRFLOW_CTX_EXECUTION_DATE='2023-11-12T16:37:27.510829+00:00' AIRFLOW_CTX_TRY_NUMBER='1' AIRFLOW_CTX_DAG_RUN_ID='manual__2023-11-12T16:37:27.510829+00:00'
[2023-11-12T16:37:34.483+0000] {sql.py:274} INFO - Executing: CREATE TABLE IF NOT EXISTS analyse_prix(
      code_commune VARCHAR(10),
      prix_moyen FLOAT
    );
[2023-11-12T16:37:34.506+0000] {taskinstance.py:1937} ERROR - Task failed with exception
Traceback (most recent call last):
  File "/home/airflow/.local/lib/python3.8/site-packages/airflow/providers/common/sql/operators/sql.py", line 275, in execute
    hook = self.get_db_hook()
  File "/home/airflow/.local/lib/python3.8/site-packages/airflow/providers/common/sql/operators/sql.py", line 186, in get_db_hook
    return self._hook
  File "/usr/local/lib/python3.8/functools.py", line 967, in __get__
    val = self.func(instance)
  File "/home/airflow/.local/lib/python3.8/site-packages/airflow/providers/common/sql/operators/sql.py", line 148, in _hook
    conn = BaseHook.get_connection(conn_id)
  File "/home/airflow/.local/lib/python3.8/site-packages/airflow/hooks/base.py", line 72, in get_connection
    conn = Connection.get_connection_from_secrets(conn_id)
  File "/home/airflow/.local/lib/python3.8/site-packages/airflow/models/connection.py", line 477, in get_connection_from_secrets
    raise AirflowNotFoundException(f"The conn_id `{conn_id}` isn't defined")
airflow.exceptions.AirflowNotFoundException: The conn_id `postgres_connexion` isn't defined
[2023-11-12T16:37:34.513+0000] {taskinstance.py:1400} INFO - Marking task as FAILED. dag_id=Projet1, task_id=create_table, execution_date=20231112T163727, start_date=20231112T163734, end_date=20231112T163734
[2023-11-12T16:37:34.529+0000] {standard_task_runner.py:104} ERROR - Failed to execute job 114 for task create_table (The conn_id `postgres_connexion` isn't defined; 29694)
[2023-11-12T16:37:34.549+0000] {local_task_job_runner.py:228} INFO - Task exited with return code 1
[2023-11-12T16:37:34.569+0000] {taskinstance.py:2778} INFO - 0 downstream tasks scheduled from follow-on schedule check
