[2023-11-09T11:38:29.179+0000] {taskinstance.py:1159} INFO - Dependencies all met for dep_context=non-requeueable deps ti=<TaskInstance: essai.t2 manual__2023-11-09T11:38:26.089681+00:00 [queued]>
[2023-11-09T11:38:29.190+0000] {taskinstance.py:1159} INFO - Dependencies all met for dep_context=requeueable deps ti=<TaskInstance: essai.t2 manual__2023-11-09T11:38:26.089681+00:00 [queued]>
[2023-11-09T11:38:29.190+0000] {taskinstance.py:1361} INFO - Starting attempt 1 of 2
[2023-11-09T11:38:29.211+0000] {taskinstance.py:1382} INFO - Executing <Task(_PythonDecoratedOperator): t2> on 2023-11-09 11:38:26.089681+00:00
[2023-11-09T11:38:29.218+0000] {standard_task_runner.py:57} INFO - Started process 8071 to run task
[2023-11-09T11:38:29.226+0000] {standard_task_runner.py:84} INFO - Running: ['***', 'tasks', 'run', 'essai', 't2', 'manual__2023-11-09T11:38:26.089681+00:00', '--job-id', '25', '--raw', '--subdir', 'DAGS_FOLDER/Part1.py', '--cfg-path', '/tmp/tmptwkn0vwo']
[2023-11-09T11:38:29.228+0000] {standard_task_runner.py:85} INFO - Job 25: Subtask t2
[2023-11-09T11:38:29.304+0000] {task_command.py:416} INFO - Running <TaskInstance: essai.t2 manual__2023-11-09T11:38:26.089681+00:00 [running]> on host fb26c01043df
[2023-11-09T11:38:29.408+0000] {taskinstance.py:1662} INFO - Exporting env vars: AIRFLOW_CTX_DAG_EMAIL='***@example.com' AIRFLOW_CTX_DAG_OWNER='***' AIRFLOW_CTX_DAG_ID='essai' AIRFLOW_CTX_TASK_ID='t2' AIRFLOW_CTX_EXECUTION_DATE='2023-11-09T11:38:26.089681+00:00' AIRFLOW_CTX_TRY_NUMBER='1' AIRFLOW_CTX_DAG_RUN_ID='manual__2023-11-09T11:38:26.089681+00:00'
[2023-11-09T11:38:29.414+0000] {taskinstance.py:1937} ERROR - Task failed with exception
Traceback (most recent call last):
  File "/home/airflow/.local/lib/python3.8/site-packages/airflow/decorators/base.py", line 221, in execute
    return_value = super().execute(context)
  File "/home/airflow/.local/lib/python3.8/site-packages/airflow/operators/python.py", line 192, in execute
    return_value = self.execute_callable()
  File "/home/airflow/.local/lib/python3.8/site-packages/airflow/operators/python.py", line 209, in execute_callable
    return self.python_callable(*self.op_args, **self.op_kwargs)
  File "/opt/airflow/dags/Part1.py", line 22, in data_transform
    data = pd.read_csv(os.path.expandvars('${AIRFLOW_HOME}/data/valeurs_foncieres.txt', sep='|', dtype="unicode",usecols = ["Type local", "Valeur fonciere","Code commune","Surface reelle bati"]))
TypeError: expandvars() got an unexpected keyword argument 'sep'
[2023-11-09T11:38:29.424+0000] {taskinstance.py:1400} INFO - Marking task as UP_FOR_RETRY. dag_id=essai, task_id=t2, execution_date=20231109T113826, start_date=20231109T113829, end_date=20231109T113829
[2023-11-09T11:38:29.437+0000] {standard_task_runner.py:104} ERROR - Failed to execute job 25 for task t2 (expandvars() got an unexpected keyword argument 'sep'; 8071)
[2023-11-09T11:38:29.480+0000] {local_task_job_runner.py:228} INFO - Task exited with return code 1
[2023-11-09T11:38:29.499+0000] {taskinstance.py:2778} INFO - 0 downstream tasks scheduled from follow-on schedule check
