[2023-11-12T22:18:13.937+0000] {taskinstance.py:1159} INFO - Dependencies all met for dep_context=non-requeueable deps ti=<TaskInstance: Projet1.Extract manual__2023-11-12T22:18:07.768607+00:00 [queued]>
[2023-11-12T22:18:13.948+0000] {taskinstance.py:1159} INFO - Dependencies all met for dep_context=requeueable deps ti=<TaskInstance: Projet1.Extract manual__2023-11-12T22:18:07.768607+00:00 [queued]>
[2023-11-12T22:18:13.949+0000] {taskinstance.py:1361} INFO - Starting attempt 1 of 1
[2023-11-12T22:18:13.966+0000] {taskinstance.py:1382} INFO - Executing <Task(PythonOperator): Extract> on 2023-11-12 22:18:07.768607+00:00
[2023-11-12T22:18:13.981+0000] {standard_task_runner.py:57} INFO - Started process 34126 to run task
[2023-11-12T22:18:13.985+0000] {standard_task_runner.py:84} INFO - Running: ['***', 'tasks', 'run', 'Projet1', 'Extract', 'manual__2023-11-12T22:18:07.768607+00:00', '--job-id', '166', '--raw', '--subdir', 'DAGS_FOLDER/Projet.py', '--cfg-path', '/tmp/tmp8_hg4lw9']
[2023-11-12T22:18:13.986+0000] {standard_task_runner.py:85} INFO - Job 166: Subtask Extract
[2023-11-12T22:18:14.089+0000] {task_command.py:416} INFO - Running <TaskInstance: Projet1.Extract manual__2023-11-12T22:18:07.768607+00:00 [running]> on host fb26c01043df
[2023-11-12T22:18:14.288+0000] {taskinstance.py:1662} INFO - Exporting env vars: AIRFLOW_CTX_DAG_OWNER='***' AIRFLOW_CTX_DAG_ID='Projet1' AIRFLOW_CTX_TASK_ID='Extract' AIRFLOW_CTX_EXECUTION_DATE='2023-11-12T22:18:07.768607+00:00' AIRFLOW_CTX_TRY_NUMBER='1' AIRFLOW_CTX_DAG_RUN_ID='manual__2023-11-12T22:18:07.768607+00:00'
[2023-11-12T22:18:14.639+0000] {taskinstance.py:1937} ERROR - Task failed with exception
Traceback (most recent call last):
  File "/home/airflow/.local/lib/python3.8/site-packages/airflow/operators/python.py", line 192, in execute
    return_value = self.execute_callable()
  File "/home/airflow/.local/lib/python3.8/site-packages/airflow/operators/python.py", line 209, in execute_callable
    return self.python_callable(*self.op_args, **self.op_kwargs)
  File "/opt/airflow/dags/Projet.py", line 22, in extract_data
    df_age.columns = ["Code tranches d'age", "Age"]
  File "/home/airflow/.local/lib/python3.8/site-packages/pandas/core/generic.py", line 6002, in __setattr__
    return object.__setattr__(self, name, value)
  File "pandas/_libs/properties.pyx", line 69, in pandas._libs.properties.AxisProperty.__set__
  File "/home/airflow/.local/lib/python3.8/site-packages/pandas/core/generic.py", line 730, in _set_axis
    self._mgr.set_axis(axis, labels)
  File "/home/airflow/.local/lib/python3.8/site-packages/pandas/core/internals/managers.py", line 225, in set_axis
    self._validate_set_axis(axis, new_labels)
  File "/home/airflow/.local/lib/python3.8/site-packages/pandas/core/internals/base.py", line 70, in _validate_set_axis
    raise ValueError(
ValueError: Length mismatch: Expected axis has 1 elements, new values have 2 elements
[2023-11-12T22:18:14.674+0000] {taskinstance.py:1400} INFO - Marking task as FAILED. dag_id=Projet1, task_id=Extract, execution_date=20231112T221807, start_date=20231112T221813, end_date=20231112T221814
[2023-11-12T22:18:14.700+0000] {standard_task_runner.py:104} ERROR - Failed to execute job 166 for task Extract (Length mismatch: Expected axis has 1 elements, new values have 2 elements; 34126)
[2023-11-12T22:18:14.738+0000] {local_task_job_runner.py:228} INFO - Task exited with return code 1
[2023-11-12T22:18:14.763+0000] {taskinstance.py:2778} INFO - 0 downstream tasks scheduled from follow-on schedule check
